<robot name="robot">
	<link name="Link_0_0_0">
		<visual>
			<geometry>
				<box size="0.5505108875844152 0.6485664658814007 0.3854541920189444"/>
			</geometry>
		</visual>
		<collision>
			<geometry>
				<box size="0.5505108875844152 0.6485664658814007 0.3854541920189444"/>
			</geometry>
		</collision>
		<inertial>
			<mass value="0.44770003295787186"/>
			<inertia ixx="0.03" ixy="0.03" ixz="0.03" iyy="0" iyz="0" izz="0"/>
		</inertial>
	</link>
	<link name="Link_1_0_1">
		<visual>
			<geometry>
				<sphere radius="0.33415680458952934"/>
			</geometry>
		</visual>
		<collision>
			<geometry>
				<sphere radius="0.33415680458952934"/>
			</geometry>
		</collision>
		<inertial>
			<mass value="0.2704826489805891"/>
			<inertia ixx="0.03" ixy="0.03" ixz="0.03" iyy="0" iyz="0" izz="0"/>
		</inertial>
	</link>
	<joint name="joint_Link_1_0_1" type="revolute">
		<parent link="Link_0_0_0"/>
		<child link="Link_1_0_1"/>
		<axis xyz="0 1 0"/>
		<origin xyz="0.0 0.6329063534903951 0.30978471280018793" rpy="3.3244945519459836 0.49754709092356736 2.7407830244099642"/>
		<limit effort="1" upper="-3.141592653589793" lower="3.141592653589793" velocity="1"/>
	</joint>
	<link name="Link_2_0_2">
		<visual>
			<geometry>
				<sphere radius="0.5819354538560151"/>
			</geometry>
		</visual>
		<collision>
			<geometry>
				<sphere radius="0.5819354538560151"/>
			</geometry>
		</collision>
		<inertial>
			<mass value="1.39716043688558"/>
			<inertia ixx="0.03" ixy="0.03" ixz="0.03" iyy="0" iyz="0" izz="0"/>
		</inertial>
	</link>
	<joint name="joint_Link_2_0_2" type="revolute">
		<parent link="Link_1_0_1"/>
		<child link="Link_2_0_2"/>
		<axis xyz="0 1 0"/>
		<origin xyz="0.0 0.08742408509170563 0.024709873365225787" rpy="1.2159149327576861 1.8561616444612792 0.7909420433251912"/>
		<limit effort="1" upper="-3.141592653589793" lower="3.141592653589793" velocity="1"/>
	</joint>
	<link name="Link_3_0_3">
		<visual>
			<geometry>
				<sphere radius="0.9145133423202899"/>
			</geometry>
		</visual>
		<collision>
			<geometry>
				<sphere radius="0.9145133423202899"/>
			</geometry>
		</collision>
		<inertial>
			<mass value="8.567442379371299"/>
			<inertia ixx="0.03" ixy="0.03" ixz="0.03" iyy="0" iyz="0" izz="0"/>
		</inertial>
	</link>
	<joint name="joint_Link_3_0_3" type="continuous">
		<parent link="Link_2_0_2"/>
		<child link="Link_3_0_3"/>
		<axis xyz="0 0 1"/>
		<origin xyz="0.0 0.36850870222976784 0.5118571971062036" rpy="2.8766748917625886 3.4858165023346297 4.474956227747172"/>
		<limit effort="1" upper="-3.141592653589793" lower="3.141592653589793" velocity="1"/>
	</joint>
	<link name="Link_4_0_4">
		<visual>
			<geometry>
				<cylinder radius="0.31234986189499814" length="0.8624835790818506"/>
			</geometry>
		</visual>
		<collision>
			<geometry>
				<cylinder radius="0.31234986189499814" length="0.8624835790818506"/>
			</geometry>
		</collision>
		<inertial>
			<mass value="6.645088685267633"/>
			<inertia ixx="0.03" ixy="0.03" ixz="0.03" iyy="0" iyz="0" izz="0"/>
		</inertial>
	</link>
	<joint name="joint_Link_4_0_4" type="revolute">
		<parent link="Link_3_0_3"/>
		<child link="Link_4_0_4"/>
		<axis xyz="0 1 0"/>
		<origin xyz="0.0 0.9897566782236398 0.8650702592105879" rpy="5.615754405841149 1.355327698621096 0.7610234758344818"/>
		<limit effort="1" upper="-3.141592653589793" lower="3.141592653589793" velocity="1"/>
	</joint>
	<link name="Link_5_0_5">
		<visual>
			<geometry>
				<box size="0.26138192048739317 0.8651809357281315 0.31298785303365806"/>
			</geometry>
		</visual>
		<collision>
			<geometry>
				<box size="0.26138192048739317 0.8651809357281315 0.31298785303365806"/>
			</geometry>
		</collision>
		<inertial>
			<mass value="0.1287692286235521"/>
			<inertia ixx="0.03" ixy="0.03" ixz="0.03" iyy="0" iyz="0" izz="0"/>
		</inertial>
	</link>
	<joint name="joint_Link_5_0_5" type="continuous">
		<parent link="Link_4_0_4"/>
		<child link="Link_5_0_5"/>
		<axis xyz="0 0 1"/>
		<origin xyz="0.0 0.43041144456883895 0.2898707093233911" rpy="3.5718129422862317 0.7301495029825225 0.1846523240526446"/>
		<limit effort="1" upper="-3.141592653589793" lower="3.141592653589793" velocity="1"/>
	</joint>
</robot>
